{
 "cells": [
  {
   "cell_type": "code",
   "execution_count": 7,
   "metadata": {},
   "outputs": [],
   "source": [
    "text = [['hello','hi'],['how are you','i am fine']]"
   ]
  },
  {
   "cell_type": "code",
   "execution_count": 13,
   "metadata": {},
   "outputs": [],
   "source": [
    "from keras.models import Sequential\n",
    "from keras.layers import Dense\n",
    "from keras.optimizers import Adam\n",
    "from keras.utils import to_categorical"
   ]
  },
  {
   "cell_type": "code",
   "execution_count": 11,
   "metadata": {},
   "outputs": [],
   "source": [
    "model = Sequential()\n",
    "model.add(Dense(32,input_shape=(2,), activation='relu'))\n",
    "\n",
    "model.compile(Adam(lr=1), loss='mean_squared_error',metrics=['accuracy'])"
   ]
  },
  {
   "cell_type": "code",
   "execution_count": 12,
   "metadata": {},
   "outputs": [
    {
     "ename": "ValueError",
     "evalue": "Error when checking model input: the list of Numpy arrays that you are passing to your model is not the size the model expected. Expected to see 1 array(s), but instead got the following list of 2 arrays: [array([['hello'],\n       ['hi']], dtype='<U5'), array([['how are you'],\n       ['i am fine']], dtype='<U11')]...",
     "output_type": "error",
     "traceback": [
      "\u001b[0;31m---------------------------------------------------------------------------\u001b[0m",
      "\u001b[0;31mValueError\u001b[0m                                Traceback (most recent call last)",
      "\u001b[0;32m<ipython-input-12-703bfc292e4b>\u001b[0m in \u001b[0;36m<module>\u001b[0;34m\u001b[0m\n\u001b[0;32m----> 1\u001b[0;31m \u001b[0mmodel\u001b[0m\u001b[0;34m.\u001b[0m\u001b[0mfit\u001b[0m\u001b[0;34m(\u001b[0m\u001b[0mtext\u001b[0m\u001b[0;34m)\u001b[0m\u001b[0;34m\u001b[0m\u001b[0;34m\u001b[0m\u001b[0m\n\u001b[0m",
      "\u001b[0;32m~/anaconda3/lib/python3.7/site-packages/keras/engine/training.py\u001b[0m in \u001b[0;36mfit\u001b[0;34m(self, x, y, batch_size, epochs, verbose, callbacks, validation_split, validation_data, shuffle, class_weight, sample_weight, initial_epoch, steps_per_epoch, validation_steps, validation_freq, max_queue_size, workers, use_multiprocessing, **kwargs)\u001b[0m\n\u001b[1;32m   1152\u001b[0m             \u001b[0msample_weight\u001b[0m\u001b[0;34m=\u001b[0m\u001b[0msample_weight\u001b[0m\u001b[0;34m,\u001b[0m\u001b[0;34m\u001b[0m\u001b[0;34m\u001b[0m\u001b[0m\n\u001b[1;32m   1153\u001b[0m             \u001b[0mclass_weight\u001b[0m\u001b[0;34m=\u001b[0m\u001b[0mclass_weight\u001b[0m\u001b[0;34m,\u001b[0m\u001b[0;34m\u001b[0m\u001b[0;34m\u001b[0m\u001b[0m\n\u001b[0;32m-> 1154\u001b[0;31m             batch_size=batch_size)\n\u001b[0m\u001b[1;32m   1155\u001b[0m \u001b[0;34m\u001b[0m\u001b[0m\n\u001b[1;32m   1156\u001b[0m         \u001b[0;31m# Prepare validation data.\u001b[0m\u001b[0;34m\u001b[0m\u001b[0;34m\u001b[0m\u001b[0;34m\u001b[0m\u001b[0m\n",
      "\u001b[0;32m~/anaconda3/lib/python3.7/site-packages/keras/engine/training.py\u001b[0m in \u001b[0;36m_standardize_user_data\u001b[0;34m(self, x, y, sample_weight, class_weight, check_array_lengths, batch_size)\u001b[0m\n\u001b[1;32m    577\u001b[0m             \u001b[0mfeed_input_shapes\u001b[0m\u001b[0;34m,\u001b[0m\u001b[0;34m\u001b[0m\u001b[0;34m\u001b[0m\u001b[0m\n\u001b[1;32m    578\u001b[0m             \u001b[0mcheck_batch_axis\u001b[0m\u001b[0;34m=\u001b[0m\u001b[0;32mFalse\u001b[0m\u001b[0;34m,\u001b[0m  \u001b[0;31m# Don't enforce the batch size.\u001b[0m\u001b[0;34m\u001b[0m\u001b[0;34m\u001b[0m\u001b[0m\n\u001b[0;32m--> 579\u001b[0;31m             exception_prefix='input')\n\u001b[0m\u001b[1;32m    580\u001b[0m \u001b[0;34m\u001b[0m\u001b[0m\n\u001b[1;32m    581\u001b[0m         \u001b[0;32mif\u001b[0m \u001b[0my\u001b[0m \u001b[0;32mis\u001b[0m \u001b[0;32mnot\u001b[0m \u001b[0;32mNone\u001b[0m\u001b[0;34m:\u001b[0m\u001b[0;34m\u001b[0m\u001b[0;34m\u001b[0m\u001b[0m\n",
      "\u001b[0;32m~/anaconda3/lib/python3.7/site-packages/keras/engine/training_utils.py\u001b[0m in \u001b[0;36mstandardize_input_data\u001b[0;34m(data, names, shapes, check_batch_axis, exception_prefix)\u001b[0m\n\u001b[1;32m    107\u001b[0m                 \u001b[0;34m'Expected to see '\u001b[0m \u001b[0;34m+\u001b[0m \u001b[0mstr\u001b[0m\u001b[0;34m(\u001b[0m\u001b[0mlen\u001b[0m\u001b[0;34m(\u001b[0m\u001b[0mnames\u001b[0m\u001b[0;34m)\u001b[0m\u001b[0;34m)\u001b[0m \u001b[0;34m+\u001b[0m \u001b[0;34m' array(s), '\u001b[0m\u001b[0;34m\u001b[0m\u001b[0;34m\u001b[0m\u001b[0m\n\u001b[1;32m    108\u001b[0m                 \u001b[0;34m'but instead got the following list of '\u001b[0m \u001b[0;34m+\u001b[0m\u001b[0;34m\u001b[0m\u001b[0;34m\u001b[0m\u001b[0m\n\u001b[0;32m--> 109\u001b[0;31m                 str(len(data)) + ' arrays: ' + str(data)[:200] + '...')\n\u001b[0m\u001b[1;32m    110\u001b[0m         \u001b[0;32melif\u001b[0m \u001b[0mlen\u001b[0m\u001b[0;34m(\u001b[0m\u001b[0mnames\u001b[0m\u001b[0;34m)\u001b[0m \u001b[0;34m>\u001b[0m \u001b[0;36m1\u001b[0m\u001b[0;34m:\u001b[0m\u001b[0;34m\u001b[0m\u001b[0;34m\u001b[0m\u001b[0m\n\u001b[1;32m    111\u001b[0m             raise ValueError(\n",
      "\u001b[0;31mValueError\u001b[0m: Error when checking model input: the list of Numpy arrays that you are passing to your model is not the size the model expected. Expected to see 1 array(s), but instead got the following list of 2 arrays: [array([['hello'],\n       ['hi']], dtype='<U5'), array([['how are you'],\n       ['i am fine']], dtype='<U11')]..."
     ]
    }
   ],
   "source": [
    "to_cat"
   ]
  }
 ],
 "metadata": {
  "kernelspec": {
   "display_name": "Python 3",
   "language": "python",
   "name": "python3"
  },
  "language_info": {
   "codemirror_mode": {
    "name": "ipython",
    "version": 3
   },
   "file_extension": ".py",
   "mimetype": "text/x-python",
   "name": "python",
   "nbconvert_exporter": "python",
   "pygments_lexer": "ipython3",
   "version": "3.7.4"
  }
 },
 "nbformat": 4,
 "nbformat_minor": 2
}
